{
  "nbformat": 4,
  "nbformat_minor": 0,
  "metadata": {
    "colab": {
      "provenance": []
    },
    "kernelspec": {
      "name": "python3",
      "display_name": "Python 3"
    },
    "language_info": {
      "name": "python"
    }
  },
  "cells": [
    {
      "cell_type": "code",
      "execution_count": null,
      "metadata": {
        "id": "7DzyK8zHVfur"
      },
      "outputs": [],
      "source": [
        "%config SqlMagic.displaylimit = None\n"
      ]
    },
    {
      "cell_type": "code",
      "source": [
        "%load_ext sql\n"
      ],
      "metadata": {
        "id": "fkpwHPzwWMiV"
      },
      "execution_count": null,
      "outputs": []
    },
    {
      "cell_type": "code",
      "source": [
        "%sql postgresql://postgres:postgres@127.0.0.1:5432/sales_data\n"
      ],
      "metadata": {
        "colab": {
          "base_uri": "https://localhost:8080/"
        },
        "id": "8UHFMgrvWUJN",
        "outputId": "52ebf713-d15d-4a6b-8f44-1d4c1e59f1ca"
      },
      "execution_count": null,
      "outputs": [
        {
          "output_type": "stream",
          "name": "stdout",
          "text": [
            "Traceback (most recent call last):\n",
            "  File \"/usr/local/lib/python3.11/dist-packages/sqlalchemy/engine/base.py\", line 145, in __init__\n",
            "    self._dbapi_connection = engine.raw_connection()\n",
            "                             ^^^^^^^^^^^^^^^^^^^^^^^\n",
            "  File \"/usr/local/lib/python3.11/dist-packages/sqlalchemy/engine/base.py\", line 3297, in raw_connection\n",
            "    return self.pool.connect()\n",
            "           ^^^^^^^^^^^^^^^^^^^\n",
            "  File \"/usr/local/lib/python3.11/dist-packages/sqlalchemy/pool/base.py\", line 449, in connect\n",
            "    return _ConnectionFairy._checkout(self)\n",
            "           ^^^^^^^^^^^^^^^^^^^^^^^^^^^^^^^^\n",
            "  File \"/usr/local/lib/python3.11/dist-packages/sqlalchemy/pool/base.py\", line 1264, in _checkout\n",
            "    fairy = _ConnectionRecord.checkout(pool)\n",
            "            ^^^^^^^^^^^^^^^^^^^^^^^^^^^^^^^^\n",
            "  File \"/usr/local/lib/python3.11/dist-packages/sqlalchemy/pool/base.py\", line 713, in checkout\n",
            "    rec = pool._do_get()\n",
            "          ^^^^^^^^^^^^^^\n",
            "  File \"/usr/local/lib/python3.11/dist-packages/sqlalchemy/pool/impl.py\", line 179, in _do_get\n",
            "    with util.safe_reraise():\n",
            "  File \"/usr/local/lib/python3.11/dist-packages/sqlalchemy/util/langhelpers.py\", line 224, in __exit__\n",
            "    raise exc_value.with_traceback(exc_tb)\n",
            "  File \"/usr/local/lib/python3.11/dist-packages/sqlalchemy/pool/impl.py\", line 177, in _do_get\n",
            "    return self._create_connection()\n",
            "           ^^^^^^^^^^^^^^^^^^^^^^^^^\n",
            "  File \"/usr/local/lib/python3.11/dist-packages/sqlalchemy/pool/base.py\", line 390, in _create_connection\n",
            "    return _ConnectionRecord(self)\n",
            "           ^^^^^^^^^^^^^^^^^^^^^^^\n",
            "  File \"/usr/local/lib/python3.11/dist-packages/sqlalchemy/pool/base.py\", line 675, in __init__\n",
            "    self.__connect()\n",
            "  File \"/usr/local/lib/python3.11/dist-packages/sqlalchemy/pool/base.py\", line 901, in __connect\n",
            "    with util.safe_reraise():\n",
            "  File \"/usr/local/lib/python3.11/dist-packages/sqlalchemy/util/langhelpers.py\", line 224, in __exit__\n",
            "    raise exc_value.with_traceback(exc_tb)\n",
            "  File \"/usr/local/lib/python3.11/dist-packages/sqlalchemy/pool/base.py\", line 897, in __connect\n",
            "    self.dbapi_connection = connection = pool._invoke_creator(self)\n",
            "                                         ^^^^^^^^^^^^^^^^^^^^^^^^^^\n",
            "  File \"/usr/local/lib/python3.11/dist-packages/sqlalchemy/engine/create.py\", line 646, in connect\n",
            "    return dialect.connect(*cargs, **cparams)\n",
            "           ^^^^^^^^^^^^^^^^^^^^^^^^^^^^^^^^^^\n",
            "  File \"/usr/local/lib/python3.11/dist-packages/sqlalchemy/engine/default.py\", line 625, in connect\n",
            "    return self.loaded_dbapi.connect(*cargs, **cparams)  # type: ignore[no-any-return]  # NOQA: E501\n",
            "           ^^^^^^^^^^^^^^^^^^^^^^^^^^^^^^^^^^^^^^^^^^^^\n",
            "  File \"/usr/local/lib/python3.11/dist-packages/psycopg2/__init__.py\", line 122, in connect\n",
            "    conn = _connect(dsn, connection_factory=connection_factory, **kwasync)\n",
            "           ^^^^^^^^^^^^^^^^^^^^^^^^^^^^^^^^^^^^^^^^^^^^^^^^^^^^^^^^^^^^^^^\n",
            "psycopg2.OperationalError: connection to server at \"127.0.0.1\", port 5432 failed: Connection refused\n",
            "\tIs the server running on that host and accepting TCP/IP connections?\n",
            "\n",
            "\n",
            "The above exception was the direct cause of the following exception:\n",
            "\n",
            "Traceback (most recent call last):\n",
            "  File \"/usr/local/lib/python3.11/dist-packages/sql/magic.py\", line 196, in execute\n",
            "    conn = sql.connection.Connection.set(\n",
            "           ^^^^^^^^^^^^^^^^^^^^^^^^^^^^^^\n",
            "  File \"/usr/local/lib/python3.11/dist-packages/sql/connection.py\", line 70, in set\n",
            "    cls.current = existing or Connection(descriptor, connect_args, creator)\n",
            "                              ^^^^^^^^^^^^^^^^^^^^^^^^^^^^^^^^^^^^^^^^^^^^^\n",
            "  File \"/usr/local/lib/python3.11/dist-packages/sql/connection.py\", line 55, in __init__\n",
            "    self.internal_connection = engine.connect()\n",
            "                               ^^^^^^^^^^^^^^^^\n",
            "  File \"/usr/local/lib/python3.11/dist-packages/sqlalchemy/engine/base.py\", line 3273, in connect\n",
            "    return self._connection_cls(self)\n",
            "           ^^^^^^^^^^^^^^^^^^^^^^^^^^\n",
            "  File \"/usr/local/lib/python3.11/dist-packages/sqlalchemy/engine/base.py\", line 147, in __init__\n",
            "    Connection._handle_dbapi_exception_noconnection(\n",
            "  File \"/usr/local/lib/python3.11/dist-packages/sqlalchemy/engine/base.py\", line 2436, in _handle_dbapi_exception_noconnection\n",
            "    raise sqlalchemy_exception.with_traceback(exc_info[2]) from e\n",
            "  File \"/usr/local/lib/python3.11/dist-packages/sqlalchemy/engine/base.py\", line 145, in __init__\n",
            "    self._dbapi_connection = engine.raw_connection()\n",
            "                             ^^^^^^^^^^^^^^^^^^^^^^^\n",
            "  File \"/usr/local/lib/python3.11/dist-packages/sqlalchemy/engine/base.py\", line 3297, in raw_connection\n",
            "    return self.pool.connect()\n",
            "           ^^^^^^^^^^^^^^^^^^^\n",
            "  File \"/usr/local/lib/python3.11/dist-packages/sqlalchemy/pool/base.py\", line 449, in connect\n",
            "    return _ConnectionFairy._checkout(self)\n",
            "           ^^^^^^^^^^^^^^^^^^^^^^^^^^^^^^^^\n",
            "  File \"/usr/local/lib/python3.11/dist-packages/sqlalchemy/pool/base.py\", line 1264, in _checkout\n",
            "    fairy = _ConnectionRecord.checkout(pool)\n",
            "            ^^^^^^^^^^^^^^^^^^^^^^^^^^^^^^^^\n",
            "  File \"/usr/local/lib/python3.11/dist-packages/sqlalchemy/pool/base.py\", line 713, in checkout\n",
            "    rec = pool._do_get()\n",
            "          ^^^^^^^^^^^^^^\n",
            "  File \"/usr/local/lib/python3.11/dist-packages/sqlalchemy/pool/impl.py\", line 179, in _do_get\n",
            "    with util.safe_reraise():\n",
            "  File \"/usr/local/lib/python3.11/dist-packages/sqlalchemy/util/langhelpers.py\", line 224, in __exit__\n",
            "    raise exc_value.with_traceback(exc_tb)\n",
            "  File \"/usr/local/lib/python3.11/dist-packages/sqlalchemy/pool/impl.py\", line 177, in _do_get\n",
            "    return self._create_connection()\n",
            "           ^^^^^^^^^^^^^^^^^^^^^^^^^\n",
            "  File \"/usr/local/lib/python3.11/dist-packages/sqlalchemy/pool/base.py\", line 390, in _create_connection\n",
            "    return _ConnectionRecord(self)\n",
            "           ^^^^^^^^^^^^^^^^^^^^^^^\n",
            "  File \"/usr/local/lib/python3.11/dist-packages/sqlalchemy/pool/base.py\", line 675, in __init__\n",
            "    self.__connect()\n",
            "  File \"/usr/local/lib/python3.11/dist-packages/sqlalchemy/pool/base.py\", line 901, in __connect\n",
            "    with util.safe_reraise():\n",
            "  File \"/usr/local/lib/python3.11/dist-packages/sqlalchemy/util/langhelpers.py\", line 224, in __exit__\n",
            "    raise exc_value.with_traceback(exc_tb)\n",
            "  File \"/usr/local/lib/python3.11/dist-packages/sqlalchemy/pool/base.py\", line 897, in __connect\n",
            "    self.dbapi_connection = connection = pool._invoke_creator(self)\n",
            "                                         ^^^^^^^^^^^^^^^^^^^^^^^^^^\n",
            "  File \"/usr/local/lib/python3.11/dist-packages/sqlalchemy/engine/create.py\", line 646, in connect\n",
            "    return dialect.connect(*cargs, **cparams)\n",
            "           ^^^^^^^^^^^^^^^^^^^^^^^^^^^^^^^^^^\n",
            "  File \"/usr/local/lib/python3.11/dist-packages/sqlalchemy/engine/default.py\", line 625, in connect\n",
            "    return self.loaded_dbapi.connect(*cargs, **cparams)  # type: ignore[no-any-return]  # NOQA: E501\n",
            "           ^^^^^^^^^^^^^^^^^^^^^^^^^^^^^^^^^^^^^^^^^^^^\n",
            "  File \"/usr/local/lib/python3.11/dist-packages/psycopg2/__init__.py\", line 122, in connect\n",
            "    conn = _connect(dsn, connection_factory=connection_factory, **kwasync)\n",
            "           ^^^^^^^^^^^^^^^^^^^^^^^^^^^^^^^^^^^^^^^^^^^^^^^^^^^^^^^^^^^^^^^\n",
            "sqlalchemy.exc.OperationalError: (psycopg2.OperationalError) connection to server at \"127.0.0.1\", port 5432 failed: Connection refused\n",
            "\tIs the server running on that host and accepting TCP/IP connections?\n",
            "\n",
            "(Background on this error at: https://sqlalche.me/e/20/e3q8)\n",
            "\n",
            "Connection info needed in SQLAlchemy format, example:\n",
            "               postgresql://username:password@hostname/dbname\n",
            "               or an existing connection: dict_keys([])\n"
          ]
        }
      ]
    },
    {
      "cell_type": "code",
      "source": [
        "\n",
        "pip install ipython-sql"
      ],
      "metadata": {
        "id": "gr-VX9gEbpZe",
        "colab": {
          "base_uri": "https://localhost:8080/"
        },
        "outputId": "8fdfd57d-e214-41b7-e327-6d091b11b760"
      },
      "execution_count": 1,
      "outputs": [
        {
          "output_type": "stream",
          "name": "stdout",
          "text": [
            "Requirement already satisfied: ipython-sql in /usr/local/lib/python3.11/dist-packages (0.5.0)\n",
            "Requirement already satisfied: prettytable in /usr/local/lib/python3.11/dist-packages (from ipython-sql) (3.16.0)\n",
            "Requirement already satisfied: ipython in /usr/local/lib/python3.11/dist-packages (from ipython-sql) (7.34.0)\n",
            "Requirement already satisfied: sqlalchemy>=2.0 in /usr/local/lib/python3.11/dist-packages (from ipython-sql) (2.0.41)\n",
            "Requirement already satisfied: sqlparse in /usr/local/lib/python3.11/dist-packages (from ipython-sql) (0.5.3)\n",
            "Requirement already satisfied: six in /usr/local/lib/python3.11/dist-packages (from ipython-sql) (1.17.0)\n",
            "Requirement already satisfied: ipython-genutils in /usr/local/lib/python3.11/dist-packages (from ipython-sql) (0.2.0)\n",
            "Requirement already satisfied: greenlet>=1 in /usr/local/lib/python3.11/dist-packages (from sqlalchemy>=2.0->ipython-sql) (3.2.3)\n",
            "Requirement already satisfied: typing-extensions>=4.6.0 in /usr/local/lib/python3.11/dist-packages (from sqlalchemy>=2.0->ipython-sql) (4.14.0)\n",
            "Requirement already satisfied: setuptools>=18.5 in /usr/local/lib/python3.11/dist-packages (from ipython->ipython-sql) (75.2.0)\n",
            "Collecting jedi>=0.16 (from ipython->ipython-sql)\n",
            "  Downloading jedi-0.19.2-py2.py3-none-any.whl.metadata (22 kB)\n",
            "Requirement already satisfied: decorator in /usr/local/lib/python3.11/dist-packages (from ipython->ipython-sql) (4.4.2)\n",
            "Requirement already satisfied: pickleshare in /usr/local/lib/python3.11/dist-packages (from ipython->ipython-sql) (0.7.5)\n",
            "Requirement already satisfied: traitlets>=4.2 in /usr/local/lib/python3.11/dist-packages (from ipython->ipython-sql) (5.7.1)\n",
            "Requirement already satisfied: prompt-toolkit!=3.0.0,!=3.0.1,<3.1.0,>=2.0.0 in /usr/local/lib/python3.11/dist-packages (from ipython->ipython-sql) (3.0.51)\n",
            "Requirement already satisfied: pygments in /usr/local/lib/python3.11/dist-packages (from ipython->ipython-sql) (2.19.1)\n",
            "Requirement already satisfied: backcall in /usr/local/lib/python3.11/dist-packages (from ipython->ipython-sql) (0.2.0)\n",
            "Requirement already satisfied: matplotlib-inline in /usr/local/lib/python3.11/dist-packages (from ipython->ipython-sql) (0.1.7)\n",
            "Requirement already satisfied: pexpect>4.3 in /usr/local/lib/python3.11/dist-packages (from ipython->ipython-sql) (4.9.0)\n",
            "Requirement already satisfied: wcwidth in /usr/local/lib/python3.11/dist-packages (from prettytable->ipython-sql) (0.2.13)\n",
            "Requirement already satisfied: parso<0.9.0,>=0.8.4 in /usr/local/lib/python3.11/dist-packages (from jedi>=0.16->ipython->ipython-sql) (0.8.4)\n",
            "Requirement already satisfied: ptyprocess>=0.5 in /usr/local/lib/python3.11/dist-packages (from pexpect>4.3->ipython->ipython-sql) (0.7.0)\n",
            "Downloading jedi-0.19.2-py2.py3-none-any.whl (1.6 MB)\n",
            "\u001b[2K   \u001b[90m━━━━━━━━━━━━━━━━━━━━━━━━━━━━━━━━━━━━━━━━\u001b[0m \u001b[32m1.6/1.6 MB\u001b[0m \u001b[31m44.7 MB/s\u001b[0m eta \u001b[36m0:00:00\u001b[0m\n",
            "\u001b[?25hInstalling collected packages: jedi\n",
            "Successfully installed jedi-0.19.2\n"
          ]
        }
      ]
    },
    {
      "cell_type": "code",
      "source": [
        "%load_ext sql\n",
        "%sql postgresql://postgres:postgres@172.17.0.2:5432/sales_data"
      ],
      "metadata": {
        "colab": {
          "base_uri": "https://localhost:8080/"
        },
        "id": "NsZKgS_iHGpK",
        "outputId": "da2a031b-fabd-4134-a2fc-a0b5253abf74"
      },
      "execution_count": 2,
      "outputs": [
        {
          "output_type": "stream",
          "name": "stdout",
          "text": [
            "Traceback (most recent call last):\n",
            "  File \"/usr/local/lib/python3.11/dist-packages/sqlalchemy/engine/base.py\", line 145, in __init__\n",
            "    self._dbapi_connection = engine.raw_connection()\n",
            "                             ^^^^^^^^^^^^^^^^^^^^^^^\n",
            "  File \"/usr/local/lib/python3.11/dist-packages/sqlalchemy/engine/base.py\", line 3297, in raw_connection\n",
            "    return self.pool.connect()\n",
            "           ^^^^^^^^^^^^^^^^^^^\n",
            "  File \"/usr/local/lib/python3.11/dist-packages/sqlalchemy/pool/base.py\", line 449, in connect\n",
            "    return _ConnectionFairy._checkout(self)\n",
            "           ^^^^^^^^^^^^^^^^^^^^^^^^^^^^^^^^\n",
            "  File \"/usr/local/lib/python3.11/dist-packages/sqlalchemy/pool/base.py\", line 1264, in _checkout\n",
            "    fairy = _ConnectionRecord.checkout(pool)\n",
            "            ^^^^^^^^^^^^^^^^^^^^^^^^^^^^^^^^\n",
            "  File \"/usr/local/lib/python3.11/dist-packages/sqlalchemy/pool/base.py\", line 713, in checkout\n",
            "    rec = pool._do_get()\n",
            "          ^^^^^^^^^^^^^^\n",
            "  File \"/usr/local/lib/python3.11/dist-packages/sqlalchemy/pool/impl.py\", line 179, in _do_get\n",
            "    with util.safe_reraise():\n",
            "  File \"/usr/local/lib/python3.11/dist-packages/sqlalchemy/util/langhelpers.py\", line 224, in __exit__\n",
            "    raise exc_value.with_traceback(exc_tb)\n",
            "  File \"/usr/local/lib/python3.11/dist-packages/sqlalchemy/pool/impl.py\", line 177, in _do_get\n",
            "    return self._create_connection()\n",
            "           ^^^^^^^^^^^^^^^^^^^^^^^^^\n",
            "  File \"/usr/local/lib/python3.11/dist-packages/sqlalchemy/pool/base.py\", line 390, in _create_connection\n",
            "    return _ConnectionRecord(self)\n",
            "           ^^^^^^^^^^^^^^^^^^^^^^^\n",
            "  File \"/usr/local/lib/python3.11/dist-packages/sqlalchemy/pool/base.py\", line 675, in __init__\n",
            "    self.__connect()\n",
            "  File \"/usr/local/lib/python3.11/dist-packages/sqlalchemy/pool/base.py\", line 901, in __connect\n",
            "    with util.safe_reraise():\n",
            "  File \"/usr/local/lib/python3.11/dist-packages/sqlalchemy/util/langhelpers.py\", line 224, in __exit__\n",
            "    raise exc_value.with_traceback(exc_tb)\n",
            "  File \"/usr/local/lib/python3.11/dist-packages/sqlalchemy/pool/base.py\", line 897, in __connect\n",
            "    self.dbapi_connection = connection = pool._invoke_creator(self)\n",
            "                                         ^^^^^^^^^^^^^^^^^^^^^^^^^^\n",
            "  File \"/usr/local/lib/python3.11/dist-packages/sqlalchemy/engine/create.py\", line 646, in connect\n",
            "    return dialect.connect(*cargs, **cparams)\n",
            "           ^^^^^^^^^^^^^^^^^^^^^^^^^^^^^^^^^^\n",
            "  File \"/usr/local/lib/python3.11/dist-packages/sqlalchemy/engine/default.py\", line 625, in connect\n",
            "    return self.loaded_dbapi.connect(*cargs, **cparams)  # type: ignore[no-any-return]  # NOQA: E501\n",
            "           ^^^^^^^^^^^^^^^^^^^^^^^^^^^^^^^^^^^^^^^^^^^^\n",
            "  File \"/usr/local/lib/python3.11/dist-packages/psycopg2/__init__.py\", line 122, in connect\n",
            "    conn = _connect(dsn, connection_factory=connection_factory, **kwasync)\n",
            "           ^^^^^^^^^^^^^^^^^^^^^^^^^^^^^^^^^^^^^^^^^^^^^^^^^^^^^^^^^^^^^^^\n",
            "psycopg2.OperationalError: connection to server at \"172.17.0.2\", port 5432 failed: Connection timed out\n",
            "\tIs the server running on that host and accepting TCP/IP connections?\n",
            "\n",
            "\n",
            "The above exception was the direct cause of the following exception:\n",
            "\n",
            "Traceback (most recent call last):\n",
            "  File \"/usr/local/lib/python3.11/dist-packages/sql/magic.py\", line 196, in execute\n",
            "    conn = sql.connection.Connection.set(\n",
            "           ^^^^^^^^^^^^^^^^^^^^^^^^^^^^^^\n",
            "  File \"/usr/local/lib/python3.11/dist-packages/sql/connection.py\", line 70, in set\n",
            "    cls.current = existing or Connection(descriptor, connect_args, creator)\n",
            "                              ^^^^^^^^^^^^^^^^^^^^^^^^^^^^^^^^^^^^^^^^^^^^^\n",
            "  File \"/usr/local/lib/python3.11/dist-packages/sql/connection.py\", line 55, in __init__\n",
            "    self.internal_connection = engine.connect()\n",
            "                               ^^^^^^^^^^^^^^^^\n",
            "  File \"/usr/local/lib/python3.11/dist-packages/sqlalchemy/engine/base.py\", line 3273, in connect\n",
            "    return self._connection_cls(self)\n",
            "           ^^^^^^^^^^^^^^^^^^^^^^^^^^\n",
            "  File \"/usr/local/lib/python3.11/dist-packages/sqlalchemy/engine/base.py\", line 147, in __init__\n",
            "    Connection._handle_dbapi_exception_noconnection(\n",
            "  File \"/usr/local/lib/python3.11/dist-packages/sqlalchemy/engine/base.py\", line 2436, in _handle_dbapi_exception_noconnection\n",
            "    raise sqlalchemy_exception.with_traceback(exc_info[2]) from e\n",
            "  File \"/usr/local/lib/python3.11/dist-packages/sqlalchemy/engine/base.py\", line 145, in __init__\n",
            "    self._dbapi_connection = engine.raw_connection()\n",
            "                             ^^^^^^^^^^^^^^^^^^^^^^^\n",
            "  File \"/usr/local/lib/python3.11/dist-packages/sqlalchemy/engine/base.py\", line 3297, in raw_connection\n",
            "    return self.pool.connect()\n",
            "           ^^^^^^^^^^^^^^^^^^^\n",
            "  File \"/usr/local/lib/python3.11/dist-packages/sqlalchemy/pool/base.py\", line 449, in connect\n",
            "    return _ConnectionFairy._checkout(self)\n",
            "           ^^^^^^^^^^^^^^^^^^^^^^^^^^^^^^^^\n",
            "  File \"/usr/local/lib/python3.11/dist-packages/sqlalchemy/pool/base.py\", line 1264, in _checkout\n",
            "    fairy = _ConnectionRecord.checkout(pool)\n",
            "            ^^^^^^^^^^^^^^^^^^^^^^^^^^^^^^^^\n",
            "  File \"/usr/local/lib/python3.11/dist-packages/sqlalchemy/pool/base.py\", line 713, in checkout\n",
            "    rec = pool._do_get()\n",
            "          ^^^^^^^^^^^^^^\n",
            "  File \"/usr/local/lib/python3.11/dist-packages/sqlalchemy/pool/impl.py\", line 179, in _do_get\n",
            "    with util.safe_reraise():\n",
            "  File \"/usr/local/lib/python3.11/dist-packages/sqlalchemy/util/langhelpers.py\", line 224, in __exit__\n",
            "    raise exc_value.with_traceback(exc_tb)\n",
            "  File \"/usr/local/lib/python3.11/dist-packages/sqlalchemy/pool/impl.py\", line 177, in _do_get\n",
            "    return self._create_connection()\n",
            "           ^^^^^^^^^^^^^^^^^^^^^^^^^\n",
            "  File \"/usr/local/lib/python3.11/dist-packages/sqlalchemy/pool/base.py\", line 390, in _create_connection\n",
            "    return _ConnectionRecord(self)\n",
            "           ^^^^^^^^^^^^^^^^^^^^^^^\n",
            "  File \"/usr/local/lib/python3.11/dist-packages/sqlalchemy/pool/base.py\", line 675, in __init__\n",
            "    self.__connect()\n",
            "  File \"/usr/local/lib/python3.11/dist-packages/sqlalchemy/pool/base.py\", line 901, in __connect\n",
            "    with util.safe_reraise():\n",
            "  File \"/usr/local/lib/python3.11/dist-packages/sqlalchemy/util/langhelpers.py\", line 224, in __exit__\n",
            "    raise exc_value.with_traceback(exc_tb)\n",
            "  File \"/usr/local/lib/python3.11/dist-packages/sqlalchemy/pool/base.py\", line 897, in __connect\n",
            "    self.dbapi_connection = connection = pool._invoke_creator(self)\n",
            "                                         ^^^^^^^^^^^^^^^^^^^^^^^^^^\n",
            "  File \"/usr/local/lib/python3.11/dist-packages/sqlalchemy/engine/create.py\", line 646, in connect\n",
            "    return dialect.connect(*cargs, **cparams)\n",
            "           ^^^^^^^^^^^^^^^^^^^^^^^^^^^^^^^^^^\n",
            "  File \"/usr/local/lib/python3.11/dist-packages/sqlalchemy/engine/default.py\", line 625, in connect\n",
            "    return self.loaded_dbapi.connect(*cargs, **cparams)  # type: ignore[no-any-return]  # NOQA: E501\n",
            "           ^^^^^^^^^^^^^^^^^^^^^^^^^^^^^^^^^^^^^^^^^^^^\n",
            "  File \"/usr/local/lib/python3.11/dist-packages/psycopg2/__init__.py\", line 122, in connect\n",
            "    conn = _connect(dsn, connection_factory=connection_factory, **kwasync)\n",
            "           ^^^^^^^^^^^^^^^^^^^^^^^^^^^^^^^^^^^^^^^^^^^^^^^^^^^^^^^^^^^^^^^\n",
            "sqlalchemy.exc.OperationalError: (psycopg2.OperationalError) connection to server at \"172.17.0.2\", port 5432 failed: Connection timed out\n",
            "\tIs the server running on that host and accepting TCP/IP connections?\n",
            "\n",
            "(Background on this error at: https://sqlalche.me/e/20/e3q8)\n",
            "\n",
            "Connection info needed in SQLAlchemy format, example:\n",
            "               postgresql://username:password@hostname/dbname\n",
            "               or an existing connection: dict_keys([])\n"
          ]
        }
      ]
    },
    {
      "cell_type": "code",
      "source": [
        "%sql postgresql://postgres:postgres@localhost/sales_data"
      ],
      "metadata": {
        "id": "wPufiPHZH2rh"
      },
      "execution_count": null,
      "outputs": []
    }
  ]
}